login_yi 用例运行失败,请检查！
Traceback (most recent call last):
  File "po\ExcuteCase.py", line 22, in wrapper
    func(*args, **kwargs)
  File "d:\python27\lib\site-packages\allure\common.py", line 62, in impl
    return func(*a, **kw)
  File "D:\lzm-demo\ui_auto\testcase\test_003_login_yi.py", line 34, in login_yi
    raise Exception(u"出错了，没有登录手机号！")
Exception: \u51fa\u9519\u4e86\uff0c\u6ca1\u6709\u767b\u5f55\u624b\u673a\u53f7\uff01

