hot_xihuan_cangxian 用例运行失败,请检查！
Traceback (most recent call last):
  File "po\ExcuteCase.py", line 22, in wrapper
    func(*args, **kwargs)
  File "d:\python27\lib\site-packages\allure\common.py", line 62, in impl
    return func(*a, **kw)
  File "D:\lzm-demo\ui_auto\testcase\test_009_hot_xihuan_cangxian.py", line 26, in hot_xihuan_cangxian
    d(resourceId="com.chinamobile.cloudapp:id/videoPauseImg").click()
  File "D:\Python27\lib\site-packages\uiautomator2\__init__.py", line 1427, in inner
    return fn(self, *args, **kwargs)
  File "D:\Python27\lib\site-packages\uiautomator2\__init__.py", line 1463, in click
    x, y = self.center()
  File "D:\Python27\lib\site-packages\uiautomator2\__init__.py", line 1477, in center
    info = self.info
  File "D:\Python27\lib\site-packages\uiautomator2\__init__.py", line 1450, in info
    return self.jsonrpc.objInfo(self.selector)
  File "D:\Python27\lib\site-packages\uiautomator2\__init__.py", line 349, in __call__
    params, http_timeout)
  File "D:\Python27\lib\site-packages\uiautomator2\__init__.py", line 371, in jsonrpc_retry_call
    return self.jsonrpc_call(*args, **kwargs)
  File "D:\Python27\lib\site-packages\uiautomator2\__init__.py", line 424, in jsonrpc_call
    raise err
UiObjectNotFoundError: -32001 Jsonrpc error: <android.support.test.uiautomator.UiObjectNotFoundException> data: UiSelector[RESOURCE_ID=com.chinamobile.cloudapp:id/videoPauseImg]

